Workbook
Name PlayerNames: OFFSET('Player Profile'!$B$5,0,0,COUNTA('Player Profile'!$B$5:$B$200),1)
Name CoachNames: Lists!$K$2:$K$10

Sheet Lists
A1: Players | B1: Sessions | C1: SessionTypes | D1: ActivityCategories | E1: MatchFormats | F1: Ratings | G1: YesNo | H1: DominantHand | I1: Backhand | J1: Levels | K1: Coaches
B2: Morning | C2: Fitness | D2: Rally | E2: Games | F2: 1 | G2: Yes | H2: Right | I2: One-handed | J2: Beginner | K2: Elan
B3: Afternoon | C3: Tennis | D3: Volley | E3: Tiebreak | F3: 2 | G3: No | H3: Left | I3: Two-handed | J3: Intermediate
B4: Evening | C4: Match | D4: Serve | E4: Super Tiebreak | F4: 3 | H4: Ambidextrous | J4: Advanced
C5: Recovery | D5: Return | E5: Set | F5: 4 | J5: Tournament
C6: Video | D6: Target Practice | E6: Practice Points | F6: 5 | J6: Member
D7: Points Play | E7: Tie | J7: Coach
D8: Match Play | E8: Other
D9: Fitness
D10: Footwork
D11: Movement
D12: Other

Sheet Player Profile
A1: Player Profile
A2: Track each player's background, current level, goals, strengths, and key focus areas. Add new players directly below the table.
A4: Player ID | B4: Player Name | C4: Age | D4: Dominant Hand | E4: Backhand | F4: Level | G4: Primary Goals | H4: Strengths | I4: Improvement Areas | J4: Notes | K4: Active?
A5: P-001 | B5: Prativ | C5: 15 | D5: Right | E5: Two-handed | F5: Advanced | H5: Game Sense | I5: Serve, Topspin | K5: Yes
A6: P-002 | B6: Bhavishnu | C6: 16 | D6: Right | E6: Two-handed | F6: Advanced | H6: Power | I6: Consistency | K6: Yes
A7: P-003 | B7: Aarish | C7: 19 | D7: Right | E7: Two-handed | F7: Advanced | H7: Variation | I7: Tactics and technique | K7: Yes
A8: P-004 | B8: Johith | C8: 13 | D8: Right | E8: Two-handed | F8: Advanced | H8: Consistency | I8: Court positioning | K8: Yes
A9: P-005 | B9: Gowtham | C9: 17 | D9: Right | E9: Two-handed | F9: Advanced | H9: Court Coverage, All court player | I9: Tactics | K9: Yes
A10: P-006 | B10: Athray | C10: 16 | D10: Right | E10: Two-handed | F10: Advanced | H10: Good Counter Puncher | I10: Serve, NetPlay | K10: Yes
A11: P-007 | B11: Arya | C11: 16 | D11: Right | E11: Two-handed | F11: Advanced | H11: Hard Hitter | I11: Consistancy and Approach | K11: Yes
A12: P-008 | B12: Alan | C12: 15 | D12: Right | E12: Two-handed | F12: Advanced | K12: Yes
A13: P-009 | B13: Fedelesh | C13: 42 | D13: Right | E13: Two-handed | F13: Members | K13: Yes
A14: P-010 | B14: Vivek | C14: 25 | D14: Right | E14: Two-handed | F14: Members | K14: Yes
A15: P-011 | B15: Stephen | C15: 25 | D15: Right | E15: Two-handed | F15: Coach | K15: Yes
A16: P-012 | B16: Srinivas | C16: 26 | D16: Right | E16: Two-handed | F16: Coach | K16: Yes
A17: P-013 | B17: Elan | C17: 28 | D17: Right | E17: Two-handed | F17: Coach | K17: Yes

Sheet Session Log
A1: Session Log
A2: One row per player activity. Blue-font columns are manual inputs. Black-font columns calculate automatically. Start/end times are optional references; enter the duration in Manual Duration and Final Duration will mirror it for reporting.
A4: Activity ID | B4: Date | C4: Session | D4: Session Type | E4: Player Name | F4: Coach | G4: Activity Category | H4: Drill / Activity | I4: Partner / Opponent | J4: Start Time | K4: End Time | L4: Manual Duration (min) | M4: Final Duration (min) | N4: Reps / Balls | O4: Successful Reps | P4: Consistency % | Q4: Target Attempts | R4: Target Hits | S4: Target Accuracy % | T4: Points Format | U4: Score For | V4: Score Against | W4: Result | X4: Intensity (1-5) | Y4: Coach Notes
A5: =IF(E5="","","SL-"&(ROW()-4)) -> SL-1 | B5: 46090 | C5: Morning | D5: Tennis | E5: Prativ | F5: Elan | G5: Rally | H5: Down the Line Rally | J5: 0.27083333 | K5: 0.27777778 | L5: 10 | M5: =IF(L5="","",L5) -> 10 | P5: =IFERROR(O5/N5,"") | S5: =IFERROR(R5/Q5,"") | W5: =IF(OR(U5="",V5=""),"",IF(U5>V5,"Win",IF(U5<V5,"Loss","Tie"))) | Y5: Logged from today's morning session snippet
A6: =IF(E6="","","SL-"&(ROW()-4)) -> SL-2 | B6: 46090 | C6: Morning | D6: Tennis | E6: Prativ | F6: Elan | G6: Rally | H6: Crosscourt Rally | J6: 0.27777778 | K6: 0.28472222 | L6: 10 | M6: =IF(L6="","",L6) -> 10 | P6: =IFERROR(O6/N6,"") | S6: =IFERROR(R6/Q6,"") | W6: =IF(OR(U6="",V6=""),"",IF(U6>V6,"Win",IF(U6<V6,"Loss","Tie")))
A7: =IF(E7="","","SL-"&(ROW()-4)) -> SL-3 | B7: 46090 | C7: Morning | D7: Tennis | E7: Prativ | F7: Elan | G7: Volley | H7: Volleys | J7: 0.28472222 | K7: 0.29166667 | L7: 10 | M7: =IF(L7="","",L7) -> 10 | P7: =IFERROR(O7/N7,"") | S7: =IFERROR(R7/Q7,"") | W7: =IF(OR(U7="",V7=""),"",IF(U7>V7,"Win",IF(U7<V7,"Loss","Tie")))
A8: =IF(E8="","","SL-"&(ROW()-4)) -> SL-4 | B8: 46090 | C8: Morning | D8: Tennis | E8: Prativ | F8: Elan | G8: Match Play | H8: Super Tiebreak | I8: Aarish | J8: 0.29166667 | K8: 0.3125 | L8: 30 | M8: =IF(L8="","",L8) -> 30 | P8: =IFERROR(O8/N8,"") | S8: =IFERROR(R8/Q8,"") | T8: Super Tiebreak | U8: 10 | V8: 6 | W8: =IF(OR(U8="",V8=""),"",IF(U8>V8,"Win",IF(U8<V8,"Loss","Tie"))) -> Win | Y8: Won 10-6
A9: =IF(E9="","","SL-"&(ROW()-4)) -> SL-5 | B9: 46090 | C9: Morning | D9: Tennis | E9: Prativ | F9: Elan | G9: Match Play | H9: Set | I9: Elan (Coach) | J9: 0.3125 | K9: 0.33333333 | L9: 30 | M9: =IF(L9="","",L9) -> 30 | P9: =IFERROR(O9/N9,"") | S9: =IFERROR(R9/Q9,"") | T9: Set | U9: 2 | V9: 6 | W9: =IF(OR(U9="",V9=""),"",IF(U9>V9,"Win",IF(U9<V9,"Loss","Tie"))) -> Loss | Y9: Set with coach
A10: =IF(E10="","","SL-"&(ROW()-4)) -> SL-6 | B10: 46090 | C10: Morning | D10: Tennis | E10: Bhavishnu | F10: Elan | G10: Rally | H10: Down the Line Rally | I10: Elan (Coach) | J10: 0.27083333 | K10: 0.27777778 | L10: 10 | M10: =IF(L10="","",L10) -> 10 | P10: =IFERROR(O10/N10,"") | S10: =IFERROR(R10/Q10,"") | W10: =IF(OR(U10="",V10=""),"",IF(U10>V10,"Win",IF(U10<V10,"Loss","Tie"))) | Y10: Logged from today's morning session snippet
A11: =IF(E11="","","SL-"&(ROW()-4)) -> SL-7 | B11: 46090 | C11: Morning | D11: Tennis | E11: Bhavishnu | F11: Elan | G11: Rally | H11: Crosscourt Rally | I11: Aarish | J11: 0.27777778 | K11: 0.28472222 | L11: 10 | M11: =IF(L11="","",L11) -> 10 | P11: =IFERROR(O11/N11,"") | S11: =IFERROR(R11/Q11,"") | W11: =IF(OR(U11="",V11=""),"",IF(U11>V11,"Win",IF(U11<V11,"Loss","Tie")))
A12: =IF(E12="","","SL-"&(ROW()-4)) -> SL-8 | B12: 46090 | C12: Morning | D12: Tennis | E12: Bhavishnu | F12: Elan | G12: Volley | H12: Volleys | I12: Elan (Coach) | J12: 0.28472222 | K12: 0.29166667 | L12: 10 | M12: =IF(L12="","",L12) -> 10 | P12: =IFERROR(O12/N12,"") | S12: =IFERROR(R12/Q12,"") | W12: =IF(OR(U12="",V12=""),"",IF(U12>V12,"Win",IF(U12<V12,"Loss","Tie")))
A13: =IF(E13="","","SL-"&(ROW()-4)) -> SL-9 | B13: 46090 | C13: Morning | D13: Tennis | E13: Aarish | F13: Elan | G13: Rally | H13: Down the Line Rally | I13: Prativ | J13: 0.27083333 | K13: 0.27777778 | M13: =IF(L13="","",L13) | P13: =IFERROR(O13/N13,"") | S13: =IFERROR(R13/Q13,"") | W13: =IF(OR(U13="",V13=""),"",IF(U13>V13,"Win",IF(U13<V13,"Loss","Tie"))) | Y13: Logged from today's morning session snippet
A14: =IF(E14="","","SL-"&(ROW()-4)) -> SL-10 | B14: 46090 | C14: Morning | D14: Tennis | E14: Aarish | F14: Elan | G14: Rally | H14: Crosscourt Rally | I14: Bhavishnu | J14: 0.27777778 | K14: 0.28472222 | M14: =IF(L14="","",L14) | P14: =IFERROR(O14/N14,"") | S14: =IFERROR(R14/Q14,"") | W14: =IF(OR(U14="",V14=""),"",IF(U14>V14,"Win",IF(U14<V14,"Loss","Tie")))
A15: =IF(E15="","","SL-"&(ROW()-4)) -> SL-11 | B15: 46090 | C15: Morning | D15: Tennis | E15: Aarish | F15: Elan | G15: Volley | H15: Volleys | I15: Prativ | J15: 0.28472222 | K15: 0.29166667 | M15: =IF(L15="","",L15) | P15: =IFERROR(O15/N15,"") | S15: =IFERROR(R15/Q15,"") | W15: =IF(OR(U15="",V15=""),"",IF(U15>V15,"Win",IF(U15<V15,"Loss","Tie")))
A16: =IF(E16="","","SL-"&(ROW()-4)) -> SL-12 | B16: 46090 | C16: Morning | D16: Tennis | E16: Aarish | F16: Elan | G16: Match Play | H16: Super Tiebreak | I16: Prativ | M16: =IF(L16="","",L16) | P16: =IFERROR(O16/N16,"") | S16: =IFERROR(R16/Q16,"") | T16: Super Tiebreak | U16: 6 | V16: 10 | W16: =IF(OR(U16="",V16=""),"",IF(U16>V16,"Win",IF(U16<V16,"Loss","Tie"))) -> Loss | Y16: Lost 6-10
A17: =IF(E17="","","SL-"&(ROW()-4)) -> SL-13 | B17: 46090 | C17: Morning | D17: Tennis | E17: Johith | F17: Elan | G17: Rally | H17: Down the Line Rally | L17: 30 | M17: =IF(L17="","",L17) -> 30 | P17: =IFERROR(O17/N17,"") | S17: =IFERROR(R17/Q17,"") | W17: =IF(OR(U17="",V17=""),"",IF(U17>V17,"Win",IF(U17<V17,"Loss","Tie"))) | Y17: Logged from today's morning session snippet
A18: =IF(E18="","","SL-"&(ROW()-4)) -> SL-14 | B18: 46090 | C18: Morning | D18: Tennis | E18: Johith | F18: Elan | G18: Rally | H18: Crosscourt Rally | L18: 30 | M18: =IF(L18="","",L18) -> 30 | P18: =IFERROR(O18/N18,"") | S18: =IFERROR(R18/Q18,"") | W18: =IF(OR(U18="",V18=""),"",IF(U18>V18,"Win",IF(U18<V18,"Loss","Tie")))
A19: =IF(E19="","","SL-"&(ROW()-4)) -> SL-15 | B19: 46090 | C19: Evening | D19: Tennis | E19: Prativ | F19: Elan | G19: Rally | H19: 2 vs 1 | I19: Stephen and Elan | J19: 0.65625 | K19: 0.66666667 | L19: 15 | M19: =IF(L19="","",L19) -> 15 | N19: 100 | O19: 60 | P19: =IFERROR(O19/N19,"") -> 0.6 | S19: =IFERROR(R19/Q19,"") | W19: =IF(OR(U19="",V19=""),"",IF(U19>V19,"Win",IF(U19<V19,"Loss","Tie")))
A20: =IF(E20="","","SL-"&(ROW()-4)) -> SL-16 | B20: 46090 | C20: Evening | D20: Tennis | E20: Prativ | F20: Elan | G20: Serve | H20: 2nd Serves | J20: 0.66666667 | K20: 0.67708333 | L20: 15 | M20: =IF(L20="","",L20) -> 15 | N20: 30 | O20: 14 | P20: =IFERROR(O20/N20,"") -> 0.46666667 | S20: =IFERROR(R20/Q20,"") | W20: =IF(OR(U20="",V20=""),"",IF(U20>V20,"Win",IF(U20<V20,"Loss","Tie")))
A21: =IF(E21="","","SL-"&(ROW()-4)) -> SL-17 | B21: 46090 | C21: Evening | D21: Tennis | E21: Prativ | F21: Elan | G21: Serve | H21: 2nd Serves | J21: 0.67708333 | K21: 0.6875 | L21: 15 | M21: =IF(L21="","",L21) -> 15 | N21: 30 | O21: 21 | P21: =IFERROR(O21/N21,"") -> 0.7 | S21: =IFERROR(R21/Q21,"") | W21: =IF(OR(U21="",V21=""),"",IF(U21>V21,"Win",IF(U21<V21,"Loss","Tie")))
A22: =IF(E22="","","SL-"&(ROW()-4)) -> SL-18 | B22: 46090 | C22: Evening | D22: Tennis | E22: Aarish | F22: Elan | G22: Serve | H22: 1st Serve | J22: 0.67708333 | K22: 0.6875 | L22: 15 | M22: =IF(L22="","",L22) -> 15 | N22: 30 | O22: 19 | P22: =IFERROR(O22/N22,"") -> 0.63333333 | S22: =IFERROR(R22/Q22,"") | W22: =IF(OR(U22="",V22=""),"",IF(U22>V22,"Win",IF(U22<V22,"Loss","Tie")))
A23: =IF(E23="","","SL-"&(ROW()-4)) -> SL-19 | B23: 46090 | C23: Evening | D23: Tennis | E23: Gowtham | F23: Elan | G23: Serve | H23: Target Serves | J23: 0.67708333 | K23: 0.6875 | L23: 15 | M23: =IF(L23="","",L23) -> 15 | N23: 30 | O23: 26 | P23: =IFERROR(O23/N23,"") -> 0.86666667 | Q23: 30 | R23: 4 | S23: =IFERROR(R23/Q23,"") -> 0.13333333 | W23: =IF(OR(U23="",V23=""),"",IF(U23>V23,"Win",IF(U23<V23,"Loss","Tie")))
A24: =IF(E24="","","SL-"&(ROW()-4)) -> SL-20 | B24: 46090 | C24: Evening | D24: Tennis | E24: Gowtham | F24: Elan | G24: Rally | H24: Down the Line Rally | I24: Elan | J24: 0.67708333 | K24: 0.6875 | L24: 15 | M24: =IF(L24="","",L24) -> 15 | P24: =IFERROR(O24/N24,"") | S24: =IFERROR(R24/Q24,"") | W24: =IF(OR(U24="",V24=""),"",IF(U24>V24,"Win",IF(U24<V24,"Loss","Tie")))
A25: =IF(E25="","","SL-"&(ROW()-4)) -> SL-21 | B25: 46090 | C25: Evening | D25: Tennis | E25: Gowtham | F25: Elan | G25: Rally | H25: Backhand Crosscourt Rally | I25: Prativ | J25: 0.6875 | K25: 0.69444444 | L25: 10 | M25: =IF(L25="","",L25) -> 10 | P25: =IFERROR(O25/N25,"") | S25: =IFERROR(R25/Q25,"") | W25: =IF(OR(U25="",V25=""),"",IF(U25>V25,"Win",IF(U25<V25,"Loss","Tie")))
A26: =IF(E26="","","SL-"&(ROW()-4)) -> SL-22 | B26: 46090 | C26: Evening | D26: Tennis | E26: Gowtham | F26: Elan | G26: Rally | H26: Forehand Crosscourt Rally | I26: Aarish | J26: 0.69444444 | K26: 0.70138889 | L26: 10 | M26: =IF(L26="","",L26) -> 10 | P26: =IFERROR(O26/N26,"") | S26: =IFERROR(R26/Q26,"") | W26: =IF(OR(U26="",V26=""),"",IF(U26>V26,"Win",IF(U26<V26,"Loss","Tie")))
A27: =IF(E27="","","SL-"&(ROW()-4)) -> SL-23 | B27: 46090 | C27: Evening | D27: Tennis | E27: Gowtham | F27: Elan | G27: Volley | H27: Volleys | I27: Prativ | J27: 0.70138889 | K27: 0.70833333 | L27: 10 | M27: =IF(L27="","",L27) -> 10 | P27: =IFERROR(O27/N27,"") | S27: =IFERROR(R27/Q27,"") | W27: =IF(OR(U27="",V27=""),"",IF(U27>V27,"Win",IF(U27<V27,"Loss","Tie")))
A28: =IF(E28="","","SL-"&(ROW()-4)) -> SL-24 | B28: 46090 | C28: Evening | D28: Tennis | E28: Gowtham | F28: Elan | G28: Match Play | H28: Super Tiebreak | I28: Prativ | J28: 0.70833333 | K28: 0.71527778 | L28: 10 | M28: =IF(L28="","",L28) -> 10 | P28: =IFERROR(O28/N28,"") | S28: =IFERROR(R28/Q28,"") | T28: Super Tiebreak | U28: 10 | V28: 1 | W28: =IF(OR(U28="",V28=""),"",IF(U28>V28,"Win",IF(U28<V28,"Loss","Tie"))) -> Win
A29: =IF(E29="","","SL-"&(ROW()-4)) -> SL-25 | B29: 46090 | C29: Evening | D29: Tennis | E29: Gowtham | F29: Elan | G29: Match Play | H29: Super Tiebreak | I29: Aarish | J29: 0.71527778 | K29: 0.72222222 | L29: 10 | M29: =IF(L29="","",L29) -> 10 | P29: =IFERROR(O29/N29,"") | S29: =IFERROR(R29/Q29,"") | T29: Super Tiebreak | U29: 10 | V29: 2 | W29: =IF(OR(U29="",V29=""),"",IF(U29>V29,"Win",IF(U29<V29,"Loss","Tie"))) -> Win
A30: =IF(E30="","","SL-"&(ROW()-4)) -> SL-26 | B30: 46090 | C30: Evening | D30: Tennis | E30: Gowtham | F30: Elan | G30: Match Play | H30: Super Tiebreak | I30: Athray | J30: 0.71527778 | K30: 0.72222222 | L30: 10 | M30: =IF(L30="","",L30) -> 10 | P30: =IFERROR(O30/N30,"") | S30: =IFERROR(R30/Q30,"") | T30: Super Tiebreak | U30: 8 | V30: 10 | W30: =IF(OR(U30="",V30=""),"",IF(U30>V30,"Win",IF(U30<V30,"Loss","Tie"))) -> Loss
A31: =IF(E31="","","SL-"&(ROW()-4)) -> SL-27 | B31: 46090 | C31: Evening | D31: Tennis | E31: Gowtham | F31: Elan | G31: Match Play | H31: Super Tiebreak | I31: Athray | J31: 0.71527778 | K31: 0.72222222 | L31: 10 | M31: =IF(L31="","",L31) -> 10 | P31: =IFERROR(O31/N31,"") | S31: =IFERROR(R31/Q31,"") | T31: Super Tiebreak | U31: 6 | V31: 10 | W31: =IF(OR(U31="",V31=""),"",IF(U31>V31,"Win",IF(U31<V31,"Loss","Tie"))) -> Loss
A32: =IF(E32="","","SL-"&(ROW()-4)) -> SL-28 | B32: 46090 | C32: Evening | D32: Tennis | E32: Athray | F32: Elan | G32: Match Play | H32: Super Tiebreak | I32: Gowtham | J32: 0.71527778 | K32: 0.72222222 | L32: 10 | M32: =IF(L32="","",L32) -> 10 | P32: =IFERROR(O32/N32,"") | S32: =IFERROR(R32/Q32,"") | T32: Super Tiebreak | U32: 10 | V32: 8 | W32: =IF(OR(U32="",V32=""),"",IF(U32>V32,"Win",IF(U32<V32,"Loss","Tie"))) -> Win
A33: =IF(E33="","","SL-"&(ROW()-4)) -> SL-29 | B33: 46090 | C33: Evening | D33: Tennis | E33: Athray | F33: Elan | G33: Match Play | H33: Super Tiebreak | I33: Gowtham | J33: 0.71527778 | K33: 0.72222222 | L33: 10 | M33: =IF(L33="","",L33) -> 10 | P33: =IFERROR(O33/N33,"") | S33: =IFERROR(R33/Q33,"") | T33: Super Tiebreak | U33: 10 | V33: 6 | W33: =IF(OR(U33="",V33=""),"",IF(U33>V33,"Win",IF(U33<V33,"Loss","Tie"))) -> Win
A34: =IF(E34="","","SL-"&(ROW()-4)) -> SL-30 | B34: 46090 | C34: Evening | D34: Tennis | E34: Prativ | F34: Elan | G34: Match Play | H34: Super Tiebreak | I34: Aarish | J34: 0.73958333 | K34: 0.75 | L34: 15 | M34: =IF(L34="","",L34) -> 15 | P34: =IFERROR(O34/N34,"") | S34: =IFERROR(R34/Q34,"") | T34: Super Tiebreak | U34: 11 | V34: 12 | W34: =IF(OR(U34="",V34=""),"",IF(U34>V34,"Win",IF(U34<V34,"Loss","Tie"))) -> Loss
A35: =IF(E35="","","SL-"&(ROW()-4)) -> SL-31 | B35: 46090 | C35: Evening | D35: Tennis | E35: Athray | F35: Elan | G35: Match Play | H35: Super Tiebreak | I35: Aarish | J35: 0.75 | K35: 0.77083333 | L35: 10 | M35: =IF(L35="","",L35) -> 10 | P35: =IFERROR(O35/N35,"") | S35: =IFERROR(R35/Q35,"") | T35: Super Tiebreak | U35: 8 | V35: 10 | W35: =IF(OR(U35="",V35=""),"",IF(U35>V35,"Win",IF(U35<V35,"Loss","Tie"))) -> Loss
A36: =IF(E36="","","SL-"&(ROW()-4)) -> SL-32 | B36: 46090 | C36: Evening | D36: Tennis | E36: Aarish | F36: Elan | G36: Match Play | H36: Super Tiebreak | I36: Prativ | J36: 0.73958333 | K36: 0.75 | L36: 15 | M36: =IF(L36="","",L36) -> 15 | P36: =IFERROR(O36/N36,"") | S36: =IFERROR(R36/Q36,"") | T36: Super Tiebreak | U36: 12 | V36: 11 | W36: =IF(OR(U36="",V36=""),"",IF(U36>V36,"Win",IF(U36<V36,"Loss","Tie"))) -> Win
A37: =IF(E37="","","SL-"&(ROW()-4)) -> SL-33 | B37: 46090 | C37: Evening | D37: Tennis | E37: Aarish | F37: Elan | G37: Match Play | H37: Super Tiebreak | I37: Athray | J37: 0.76041667 | K37: 0.77083333 | L37: 15 | M37: =IF(L37="","",L37) -> 15 | P37: =IFERROR(O37/N37,"") | S37: =IFERROR(R37/Q37,"") | T37: Super Tiebreak | U37: 10 | V37: 8 | W37: =IF(OR(U37="",V37=""),"",IF(U37>V37,"Win",IF(U37<V37,"Loss","Tie"))) -> Win
A38: =IF(E38="","","SL-"&(ROW()-4)) -> SL-34 | B38: 46090 | C38: Evening | D38: Tennis | E38: Prativ | F38: Elan | G38: Match Play | H38: Super Tiebreak | I38: Arya | J38: 0.73958333 | K38: 0.75 | L38: 15 | M38: =IF(L38="","",L38) -> 15 | P38: =IFERROR(O38/N38,"") | S38: =IFERROR(R38/Q38,"") | T38: Super Tiebreak | U38: 10 | V38: 6 | W38: =IF(OR(U38="",V38=""),"",IF(U38>V38,"Win",IF(U38<V38,"Loss","Tie"))) -> Win
A39: =IF(E39="","","SL-"&(ROW()-4)) -> SL-35 | B39: 46090 | C39: Evening | D39: Tennis | E39: Prativ | F39: Elan | G39: Match Play | H39: Super Tiebreak | I39: Arya | J39: 0.75 | K39: 0.76041667 | L39: 15 | M39: =IF(L39="","",L39) -> 15 | P39: =IFERROR(O39/N39,"") | S39: =IFERROR(R39/Q39,"") | T39: Super Tiebreak | U39: 10 | V39: 8 | W39: =IF(OR(U39="",V39=""),"",IF(U39>V39,"Win",IF(U39<V39,"Loss","Tie"))) -> Win
A40: =IF(E40="","","SL-"&(ROW()-4)) -> SL-36 | B40: 46090 | C40: Evening | D40: Tennis | E40: Arya | F40: Elan | G40: Match Play | H40: Super Tiebreak | I40: Prativ | J40: 0.73958333 | K40: 0.75 | L40: 15 | M40: =IF(L40="","",L40) -> 15 | P40: =IFERROR(O40/N40,"") | S40: =IFERROR(R40/Q40,"") | T40: Super Tiebreak | U40: 6 | V40: 10 | W40: =IF(OR(U40="",V40=""),"",IF(U40>V40,"Win",IF(U40<V40,"Loss","Tie"))) -> Loss
A41: =IF(E40="","","SL-"&(ROW()-4)) -> SL-37 | B41: 46090 | C41: Evening | D41: Tennis | E41: Arya | F41: Elan | G41: Match Play | H41: Super Tiebreak | I41: Prativ | J41: 0.75 | K41: 0.76041667 | L41: 15 | M41: =IF(L41="","",L41) -> 15 | P41: =IFERROR(O41/N41,"") | S41: =IFERROR(R41/Q41,"") | T41: Super Tiebreak | U41: 8 | V41: 10 | W41: =IF(OR(U41="",V41=""),"",IF(U41>V41,"Win",IF(U41<V41,"Loss","Tie"))) -> Loss
...

Sheet Skill Metrics
A1: Skill Metrics
A2: Use this sheet for drill quality: consistency, rally length, target accuracy, errors, and coach rating. Leave non-applicable cells blank.
A4: Metric ID | B4: Player Name | C4: Date | D4: Session | E4: Drill Category | F4: Drill Name | G4: Duration (min) | H4: Attempts / Balls | I4: Successful / In | J4: Consistency % | K4: Target Attempts | L4: Target Hits | M4: Target Accuracy % | N4: Avg Rally Length | O4: Best Rally Length | P4: Unforced Errors | Q4: Coach Rating (1-5) | R4: Notes
A5: =IF(B5="","","SM-"&(ROW()-4)) -> SM-1 | B5: Prativ | C5: 46090 | D5: Morning | E5: Rally | F5: Down the Line Rally | J5: =IFERROR(I5/H5,"") | M5: =IFERROR(L5/K5,"") | R5: Morning session imported from notes
A6: =IF(B6="","","SM-"&(ROW()-4)) -> SM-2 | B6: Prativ | C6: 46090 | D6: Morning | E6: Rally | F6: Crosscourt Rally | J6: =IFERROR(I6/H6,"") | M6: =IFERROR(L6/K6,"")
A7: =IF(B7="","","SM-"&(ROW()-4)) -> SM-3 | B7: Prativ | C7: 46090 | D7: Morning | E7: Volley | F7: Volleys | J7: =IFERROR(I7/H7,"") | M7: =IFERROR(L7/K7,"")
A8: =IF(B8="","","SM-"&(ROW()-4)) -> SM-4 | B8: Bhavishnu | C8: 46090 | D8: Morning | E8: Rally | F8: Down the Line Rally | J8: =IFERROR(I8/H8,"") | M8: =IFERROR(L8/K8,"") | R8: Morning session imported from notes
A9: =IF(B9="","","SM-"&(ROW()-4)) -> SM-5 | B9: Bhavishnu | C9: 46090 | D9: Morning | E9: Rally | F9: Crosscourt Rally | J9: =IFERROR(I9/H9,"") | M9: =IFERROR(L9/K9,"")
A10: =IF(B10="","","SM-"&(ROW()-4)) -> SM-6 | B10: Bhavishnu | C10: 46090 | D10: Morning | E10: Volley | F10: Volleys | J10: =IFERROR(I10/H10,"") | M10: =IFERROR(L10/K10,"")
A11: =IF(B11="","","SM-"&(ROW()-4)) -> SM-7 | B11: Aarish | C11: 46090 | D11: Morning | E11: Rally | F11: Down the Line Rally | J11: =IFERROR(I11/H11,"") | M11: =IFERROR(L11/K11,"") | R11: Morning session imported from notes
A12: =IF(B12="","","SM-"&(ROW()-4)) -> SM-8 | B12: Aarish | C12: 46090 | D12: Morning | E12: Rally | F12: Crosscourt Rally | J12: =IFERROR(I12/H12,"") | M12: =IFERROR(L12/K12,"")
A13: =IF(B13="","","SM-"&(ROW()-4)) -> SM-9 | B13: Aarish | C13: 46090 | D13: Morning | E13: Volley | F13: Volleys | J13: =IFERROR(I13/H13,"") | M13: =IFERROR(L13/K13,"")
A14: =IF(B14="","","SM-"&(ROW()-4)) -> SM-10 | B14: Johith | C14: 46090 | D14: Morning | E14: Rally | F14: Down the Line Rally | J14: =IFERROR(I14/H14,"") | M14: =IFERROR(L14/K14,"") | R14: Morning session imported from notes
A15: =IF(B15="","","SM-"&(ROW()-4)) -> SM-11 | B15: Johith | C15: 46090 | D15: Morning | E15: Rally | F15: Crosscourt Rally | J15: =IFERROR(I15/H15,"") | M15: =IFERROR(L15/K15,"")

Sheet Match Data
A1: Match Data
A2: Track competitive outcomes separately: score, result, ratings, winners/errors, and tactical notes.
A4: Match ID | B4: Player Name | C4: Date | D4: Session | E4: Opponent | F4: Format | G4: Score For | H4: Score Against | I4: Result | J4: Serve Rating (1-5) | K4: Return Rating (1-5) | L4: Movement (1-5) | M4: Decision Making (1-5) | N4: Mental Composure (1-5) | O4: Winner Count | P4: Error Count | Q4: Notes
A5: =IF(B5="","","MD-"&(ROW()-4)) -> MD-1 | B5: Prativ | C5: 46090 | D5: Morning | E5: Aarish | F5: Super Tiebreak | G5: 10 | H5: 6 | I5: =IF(OR(G5="",H5=""),"",IF(G5>H5,"Win",IF(G5<H5,"Loss","Tie"))) -> Win | Q5: Won super tiebreak 10-6
A6: =IF(B6="","","MD-"&(ROW()-4)) -> MD-2 | B6: Aarish | C6: 46090 | D6: Morning | E6: Prativ | F6: Super Tiebreak | G6: 6 | H6: 10 | I6: =IF(OR(G6="",H6=""),"",IF(G6>H6,"Win",IF(G6<H6,"Loss","Tie"))) -> Loss | Q6: Lost super tiebreak 6-10
A7: =IF(B7="","","MD-"&(ROW()-4)) -> MD-3 | B7: Prativ | C7: 46090 | D7: Morning | E7: Elan | F7: Set | G7: 2 | H7: 6 | I7: =IF(OR(G7="",H7=""),"",IF(G7>H7,"Win",IF(G7<H7,"Loss","Tie"))) -> Loss | Q7: Set with coach
A8: =IF(B8="","","MD-"&(ROW()-4)) -> MD-4 | B8: Prativ | C8: 46090 | D8: Evening | E8: Gowtham | F8: Super Tiebreak | G8: 1 | H8: 10 | I8: =IF(OR(G8="",H8=""),"",IF(G8>H8,"Win",IF(G8<H8,"Loss","Tie"))) -> Loss
A9: =IF(B9="","","MD-"&(ROW()-4)) -> MD-5 | B9: Aarish | C9: 46090 | D9: Evening | E9: Gowtham | F9: Super Tiebreak | G9: 2 | H9: 10 | I9: =IF(OR(G9="",H9=""),"",IF(G9>H9,"Win",IF(G9<H9,"Loss","Tie"))) -> Loss
A10: =IF(B10="","","MD-"&(ROW()-4)) -> MD-6 | B10: Gowtham | C10: 46090 | D10: Evening | E10: Prativ | F10: Super Tiebreak | G10: 10 | H10: 1 | I10: =IF(OR(G10="",H10=""),"",IF(G10>H10,"Win",IF(G10<H10,"Loss","Tie"))) -> Win
A11: =IF(B11="","","MD-"&(ROW()-4)) -> MD-7 | B11: Gowtham | C11: 46090 | D11: Evening | E11: Aarish | F11: Super Tiebreak | G11: 10 | H11: 2 | I11: =IF(OR(G11="",H11=""),"",IF(G11>H11,"Win",IF(G11<H11,"Loss","Tie"))) -> Win
A12: =IF(B12="","","MD-"&(ROW()-4)) -> MD-8 | B12: Gowtham | C12: 46090 | D12: Evening | E12: Athray | F12: Super Tiebreak | G12: 8 | H12: 10 | I12: =IF(OR(G12="",H12=""),"",IF(G12>H12,"Win",IF(G12<H12,"Loss","Tie"))) -> Loss
A13: =IF(B13="","","MD-"&(ROW()-4)) -> MD-9 | B13: Gowtham | C13: 46090 | D13: Evening | E13: Athray | F13: Super Tiebreak | G13: 7 | H13: 10 | I13: =IF(OR(G13="",H13=""),"",IF(G13>H13,"Win",IF(G13<H13,"Loss","Tie"))) -> Loss
A14: =IF(B14="","","MD-"&(ROW()-4)) -> MD-10 | B14: Athray | C14: 46090 | D14: Evening | E14: Gowtham | F14: Super Tiebreak | G14: 10 | H14: 8 | I14: =IF(OR(G14="",H14=""),"",IF(G14>H14,"Win",IF(G14<H14,"Loss","Tie"))) -> Win
A15: =IF(B15="","","MD-"&(ROW()-4)) -> MD-11 | B15: Athray | C15: 46090 | D15: Evening | E15: Gowtham | F15: Super Tiebreak | G15: 10 | H15: 7 | I15: =IF(OR(G15="",H15=""),"",IF(G15>H15,"Win",IF(G15<H15,"Loss","Tie"))) -> Win
A16: =IF(B16="","","MD-"&(ROW()-4)) -> MD-12 | B16: Prativ | C16: 46090 | D16: Evening | E16: Aarish | F16: Super Tiebreak | G16: 11 | H16: 12 | I16: =IF(OR(G16="",H16=""),"",IF(G16>H16,"Win",IF(G16<H16,"Loss","Tie"))) -> Loss
A17: =IF(B17="","","MD-"&(ROW()-4)) -> MD-13 | B17: Aarish | C17: 46090 | D17: Evening | E17: Prativ | F17: Super Tiebreak | G17: 12 | H17: 11 | I17: =IF(OR(G17="",H17=""),"",IF(G17>H17,"Win",IF(G17<H17,"Loss","Tie"))) -> Win
A18: =IF(B18="","","MD-"&(ROW()-4)) -> MD-14 | B18: Athray | C18: 46090 | D18: Evening | E18: Aarish | F18: Super Tiebreak | G18: 8 | H18: 10 | I18: =IF(OR(G18="",H18=""),"",IF(G18>H18,"Win",IF(G18<H18,"Loss","Tie"))) -> Loss
A19: =IF(B19="","","MD-"&(ROW()-4)) -> MD-15 | B19: Aarish | C19: 46090 | D19: Evening | E19: Athray | F19: Super Tiebreak | G19: 10 | H19: 8 | I19: =IF(OR(G19="",H19=""),"",IF(G19>H19,"Win",IF(G19<H19,"Loss","Tie"))) -> Win
... A23: =IF(B23="","","MD-"&(ROW()-4)) -> MD-19 | B23: Arya | C23: 46090 | D23: Evening | E23: Prativ | F23: Super Tiebreak | G23: 6 | H23: 10 | I23: =IF(OR(G23="",H23=""),"",IF(G23>H23,"Win",IF(G23<H23,"Loss","Tie"))) -> Loss
A24: =IF(B24="","","MD-"&(ROW()-4)) -> MD-20 | B24: Prativ | C24: 46091 | D24: Evening | E24: Athray | F24: Set | G24: 4 | H24: 6 | I24: =IF(OR(G24="",H24=""),"",IF(G24>H24,"Win",IF(G24<H24,"Loss","Tie"))) -> Loss | J24: 4 | K24: 3 | L24: 3 | M24: 4
A25: =IF(B25="","","MD-"&(ROW()-4)) -> MD-21 | B25: Athray | C25: 46091 | D25: Evening | E25: Athray | F25: Set | G25: 6 | H25: 4 | I25: =IF(OR(G25="",H25=""),"",IF(G25>H25,"Win",IF(G25<H25,"Loss","Tie"))) -> Win | J25: 3 | K25: 3 | L25: 3 | M25: 3
A26: =IF(B26="","","MD-"&(ROW()-4)) -> MD-22 | B26: Athray | C26: 46091 | D26: Evening | E26: Aarish | F26: Set | G26: 3 | H26: 4 | I26: =IF(OR(G26="",H26=""),"",IF(G26>H26,"Win",IF(G26<H26,"Loss","Tie"))) -> Loss | J26: 3 | K26: 2 | L26: 4 | M26: 2
A27: =IF(B27="","","MD-"&(ROW()-4)) -> MD-23 | B27: Aarish | C27: 46091 | D27: Evening | E27: Athray | F27: Set | G27: 4 | H27: 3 | I27: =IF(OR(G27="",H27=""),"",IF(G27>H27,"Win",IF(G27<H27,"Loss","Tie"))) -> Win | J27: 3 | K27: 2 | L27: 3 | M27: 2
A28: =IF(B28="","","MD-"&(ROW()-4)) | I28: =IF(OR(G28="",H28=""),"",IF(G28>H28,"Win",IF(G28<H28,"Loss","Tie")))
A29: =IF(B29="","","MD-"&(ROW()-4)) | I29: =IF(OR(G29="",H29=""),"",IF(G29>H29,"Win",IF(G29<H29,"Loss","Tie")))
A30: =IF(B30="","","MD-"&(ROW()-4)) | I30: =IF(OR(G30="",H30=""),"",IF(G30>H30,"Win",IF(G30<H30,"Loss","Tie")))
A31: =IF(B31="","","MD-"&(ROW()-4)) | I31: =IF(OR(G31="",H31=""),"",IF(G31>H31,"Win",IF(G31<H31,"Loss","Tie")))
A32: =IF(B32="","","MD-"&(ROW()-4)) | I32: =IF(OR(G32="",H32=""),"",IF(G32>H32,"Win",IF(G32<H32,"Loss","Tie")))
A33: =IF(B33="","","MD-"&(ROW()-4)) | I33: =IF(OR(G33="",H33=""),"",IF(G33>H33,"Win",IF(G33<H33,"Loss","Tie")))
A34: =IF(B34="","","MD-"&(ROW()-4)) | I34: =IF(OR(G34="",H34=""),"",IF(G34>H34,"Win",IF(G34<H34,"Loss","Tie")))
A35: =IF(B35="","","MD-"&(ROW()-4)) | I35: =IF(OR(G35="",H35=""),"",IF(G35>H35,"Win",IF(G35<H35,"Loss","Tie")))
A36: =IF(B36="","","MD-"&(ROW()-4)) | I36: =IF(OR(G36="",H36=""),"",IF(G36>H36,"Win",IF(G36<H36,"Loss","Tie")))
A37: =IF(B37="","","MD-"&(ROW()-4)) | I37: =IF(OR(G37="",H37=""),"",IF(G37>H37,"Win",IF(G37<H37,"Loss","Tie")))
A38: =IF(B38="","","MD-"&(ROW()-4)) | I38: =IF(OR(G38="",H38=""),"",IF(G38>H38,"Win",IF(G38<H38,"Loss","Tie")))
A39: =IF(B39="","","MD-"&(ROW()-4)) | I39: =IF(OR(G39="",H39=""),"",IF(G39>H39,"Win",IF(G39<H39,"Loss","Tie")))
... A61: =IF(B61="","","MD-"&(ROW()-4)) | I61: =IF(OR(G61="",H61=""),"",IF(G61>H61,"Win",IF(G61<H61,"Loss","Tie")))
A62: =IF(B62="","","MD-"&(ROW()-4))
A63: =IF(B63="","","MD-"&(ROW()-4))
A64: =IF(B64="","","MD-"&(ROW()-4))
A65: =IF(B65="","","MD-"&(ROW()-4))
...

Sheet Performance Dashboard
A1: Performance Dashboard | S1: Key KPIs | T1: Current
A2: This dashboard pulls from the Player Profile, Session Log, Skill Metrics, and Match Data sheets. Add new profiles and logs, then refresh/recalculate in Excel if needed. | S2: Active Players | T2: =COUNTIF(B5:B54,"Yes") -> 13
S3: Total Practice Minutes | T3: =SUM(D5:D54) -> 1270
A4: Player Name | B4: Active? | C4: Practice Entries | D4: Total Practice Minutes | E4: Skill Entries | F4: Avg Rally Consistency | G4: Avg Target Accuracy | H4: Avg Best Rally Length | I4: Match Entries | J4: Match Wins | K4: Match Win Rate | L4: Avg Serve Rating | M4: Avg Return Rating | N4: Avg Movement | O4: Avg Decision Making | P4: Last Practice Date | Q4: Last Match Date | S4: Avg Match Win Rate | T4: =IFERROR(AVERAGE(K5:K54),"") -> 0.42571429
A5: =IF('Player Profile'!B5="","",'Player Profile'!B5) -> Prativ | B5: =IF(A5="","",'Player Profile'!K5) -> Yes | C5: =IF(A5="","",COUNTIFS('Session Log'!$E$5:$E$2000,$A5)) -> 17 | D5: =IF(A5="","",SUMIFS('Session Log'!$M$5:$M$2000,'Session Log'!$E$5:$E$2000,$A5)) -> 420 | E5: =IF(A5="","",COUNTIFS('Skill Metrics'!$B$5:$B$2000,$A5)) -> 3 | F5: =IFERROR(AVERAGEIFS('Skill Metrics'!$J$5:$J$2000,'Skill Metrics'!$B$5:$B$2000,$A5),"") | G5: =IFERROR(AVERAGEIFS('Skill Metrics'!$M$5:$M$2000,'Skill Metrics'!$B$5:$B$2000,$A5),"") | H5: =IFERROR(AVERAGEIFS('Skill Metrics'!$O$5:$O$2000,'Skill Metrics'!$B$5:$B$2000,$A5),"") | I5: =IF(A5="","",COUNTIFS('Match Data'!$B$5:$B$2000,$A5)) -> 7 | J5: =IF(A5="","",COUNTIFS('Match Data'!$B$5:$B$2000,$A5,'Match Data'!$I$5:$I$2000,"Win")) -> 3 | K5: =IFERROR(J5/I5,"") -> 0.42857143 | L5: =IFERROR(AVERAGEIFS('Match Data'!$J$5:$J$2000,'Match Data'!$B$5:$B$2000,$A5),"") -> 4 | M5: =IFERROR(AVERAGEIFS('Match Data'!$K$5:$K$2000,'Match Data'!$B$5:$B$2000,$A5),"") -> 3 | N5: =IFERROR(AVERAGEIFS('Match Data'!$L$5:$L$2000,'Match Data'!$B$5:$B$2000,$A5),"") -> 3 | O5: =IFERROR(AVERAGEIFS('Match Data'!$M$5:$M$2000,'Match Data'!$B$5:$B$2000,$A5),"") -> 4 | P5: =IFERROR(maxifs('Session Log'!$B$5:$B$2000,'Session Log'!$E$5:$E$2000,$A5),"") -> 46091 | Q5: =IFERROR(maxifs('Match Data'!$C$5:$C$2000,'Match Data'!$B$5:$B$2000,$A5),"") -> 46091 | S5: Avg Rally Consistency | T5: =IFERROR(AVERAGE(F5:F54),"")
A6: =IF('Player Profile'!B6="","",'Player Profile'!B6) -> Bhavishnu | B6: =IF(A6="","",'Player Profile'!K6) -> Yes | C6: =IF(A6="","",COUNTIFS('Session Log'!$E$5:$E$2000,$A6)) -> 11 | D6: =IF(A6="","",SUMIFS('Session Log'!$M$5:$M$2000,'Session Log'!$E$5:$E$2000,$A6)) -> 180 | E6: =IF(A6="","",COUNTIFS('Skill Metrics'!$B$5:$B$2000,$A6)) -> 3 | F6: =IFERROR(AVERAGEIFS('Skill Metrics'!$J$5:$J$2000,'Skill Metrics'!$B$5:$B$2000,$A6),"") | G6: =IFERROR(AVERAGEIFS('Skill Metrics'!$M$5:$M$2000,'Skill Metrics'!$B$5:$B$2000,$A6),"") | H6: =IFERROR(AVERAGEIFS('Skill Metrics'!$O$5:$O$2000,'Skill Metrics'!$B$5:$B$2000,$A6),"") | I6: =IF(A6="","",COUNTIFS('Match Data'!$B$5:$B$2000,$A6)) -> 0 | J6: =IF(A6="","",COUNTIFS('Match Data'!$B$5:$B$2000,$A6,'Match Data'!$I$5:$I$2000,"Win")) -> 0 | K6: =IFERROR(J6/I6,"") | L6: =IFERROR(AVERAGEIFS('Match Data'!$J$5:$J$2000,'Match Data'!$B$5:$B$2000,$A6),"") | M6: =IFERROR(AVERAGEIFS('Match Data'!$K$5:$K$2000,'Match Data'!$B$5:$B$2000,$A6),"") | N6: =IFERROR(AVERAGEIFS('Match Data'!$L$5:$L$2000,'Match Data'!$B$5:$B$2000,$A6),"") | O6: =IFERROR(AVERAGEIFS('Match Data'!$M$5:$M$2000,'Match Data'!$B$5:$B$2000,$A6),"") | P6: =IFERROR(maxifs('Session Log'!$B$5:$B$2000,'Session Log'!$E$5:$E$2000,$A6),"") -> 46091 | Q6: =IFERROR(maxifs('Match Data'!$C$5:$C$2000,'Match Data'!$B$5:$B$2000,$A6),"") -> 0
A7: =IF('Player Profile'!B7="","",'Player Profile'!B7) -> Aarish | B7: =IF(A7="","",'Player Profile'!K7) -> Yes | C7: =IF(A7="","",COUNTIFS('Session Log'!$E$5:$E$2000,$A7)) -> 12 | D7: =IF(A7="","",SUMIFS('Session Log'!$M$5:$M$2000,'Session Log'!$E$5:$E$2000,$A7)) -> 105 | E7: =IF(A7="","",COUNTIFS('Skill Metrics'!$B$5:$B$2000,$A7)) -> 3 | F7: =IFERROR(AVERAGEIFS('Skill Metrics'!$J$5:$J$2000,'Skill Metrics'!$B$5:$B$2000,$A7),"") | G7: =IFERROR(AVERAGEIFS('Skill Metrics'!$M$5:$M$2000,'Skill Metrics'!$B$5:$B$2000,$A7),"") | H7: =IFERROR(AVERAGEIFS('Skill Metrics'!$O$5:$O$2000,'Skill Metrics'!$B$5:$B$2000,$A7),"") | I7: =IF(A7="","",COUNTIFS('Match Data'!$B$5:$B$2000,$A7)) -> 5 | J7: =IF(A7="","",COUNTIFS('Match Data'!$B$5:$B$2000,$A7,'Match Data'!$I$5:$I$2000,"Win")) -> 3 | K7: =IFERROR(J7/I7,"") -> 0.6 | L7: =IFERROR(AVERAGEIFS('Match Data'!$J$5:$J$2000,'Match Data'!$B$5:$B$2000,$A7),"") -> 3 | M7: =IFERROR(AVERAGEIFS('Match Data'!$K$5:$K$2000,'Match Data'!$B$5:$B$2000,$A7),"") -> 2 | N7: =IFERROR(AVERAGEIFS('Match Data'!$L$5:$L$2000,'Match Data'!$B$5:$B$2000,$A7),"") -> 3 | O7: =IFERROR(AVERAGEIFS('Match Data'!$M$5:$M$2000,'Match Data'!$B$5:$B$2000,$A7),"") -> 2 | P7: =IFERROR(maxifs('Session Log'!$B$5:$B$2000,'Session Log'!$E$5:$E$2000,$A7),"") -> 46091 | Q7: =IFERROR(maxifs('Match Data'!$C$5:$C$2000,'Match Data'!$B$5:$B$2000,$A7),"") -> 46091
A8: =IF('Player Profile'!B8="","",'Player Profile'!B8) -> Johith | B8: =IF(A8="","",'Player Profile'!K8) -> Yes | C8: =IF(A8="","",COUNTIFS('Session Log'!$E$5:$E$2000,$A8)) -> 3 | D8: =IF(A8="","",SUMIFS('Session Log'!$M$5:$M$2000,'Session Log'!$E$5:$E$2000,$A8)) -> 120 | E8: =IF(A8="","",COUNTIFS('Skill Metrics'!$B$5:$B$2000,$A8)) -> 2 | F8: =IFERROR(AVERAGEIFS('Skill Metrics'!$J$5:$J$2000,'Skill Metrics'!$B$5:$B$2000,$A8),"") | G8: =IFERROR(AVERAGEIFS('Skill Metrics'!$M$5:$M$2000,'Skill Metrics'!$B$5:$B$2000,$A8),"") | H8: =IFERROR(AVERAGEIFS('Skill Metrics'!$O$5:$O$2000,'Skill Metrics'!$B$5:$B$2000,$A8),"") | I8: =IF(A8="","",COUNTIFS('Match Data'!$B$5:$B$2000,$A8)) -> 0 | J8: =IF(A8="","",COUNTIFS('Match Data'!$B$5:$B$2000,$A8,'Match Data'!$I$5:$I$2000,"Win")) -> 0 | K8: =IFERROR(J8/I8,"") | L8: =IFERROR(AVERAGEIFS('Match Data'!$J$5:$J$2000,'Match Data'!$B$5:$B$2000,$A8),"") | M8: =IFERROR(AVERAGEIFS('Match Data'!$K$5:$K$2000,'Match Data'!$B$5:$B$2000,$A8),"") | N8: =IFERROR(AVERAGEIFS('Match Data'!$L$5:$L$2000,'Match Data'!$B$5:$B$2000,$A8),"") | O8: =IFERROR(AVERAGEIFS('Match Data'!$M$5:$M$2000,'Match Data'!$B$5:$B$2000,$A8),"") | P8: =IFERROR(maxifs('Session Log'!$B$5:$B$2000,'Session Log'!$E$5:$E$2000,$A8),"") -> 46091 | Q8: =IFERROR(maxifs('Match Data'!$C$5:$C$2000,'Match Data'!$B$5:$B$2000,$A8),"") -> 0
A9: =IF('Player Profile'!B9="","",'Player Profile'!B9) -> Gowtham | B9: =IF(A9="","",'Player Profile'!K9) -> Yes | C9: =IF(A9="","",COUNTIFS('Session Log'!$E$5:$E$2000,$A9)) -> 13 | D9: =IF(A9="","",SUMIFS('Session Log'!$M$5:$M$2000,'Session Log'!$E$5:$E$2000,$A9)) -> 200 | E9: =IF(A9="","",COUNTIFS('Skill Metrics'!$B$5:$B$2000,$A9)) -> 0 | F9: =IFERROR(AVERAGEIFS('Skill Metrics'!$J$5:$J$2000,'Skill Metrics'!$B$5:$B$2000,$A9),"") | G9: =IFERROR(AVERAGEIFS('Skill Metrics'!$M$5:$M$2000,'Skill Metrics'!$B$5:$B$2000,$A9),"") | H9: =IFERROR(AVERAGEIFS('Skill Metrics'!$O$5:$O$2000,'Skill Metrics'!$B$5:$B$2000,$A9),"") | I9: =IF(A9="","",COUNTIFS('Match Data'!$B$5:$B$2000,$A9)) -> 4 | J9: =IF(A9="","",COUNTIFS('Match Data'!$B$5:$B$2000,$A9,'Match Data'!$I$5:$I$2000,"Win")) -> 2 | K9: =IFERROR(J9/I9,"") -> 0.5 | L9: =IFERROR(AVERAGEIFS('Match Data'!$J$5:$J$2000,'Match Data'!$B$5:$B$2000,$A9),"") | M9: =IFERROR(AVERAGEIFS('Match Data'!$K$5:$K$2000,'Match Data'!$B$5:$B$2000,$A9),"") | N9: =IFERROR(AVERAGEIFS('Match Data'!$L$5:$L$2000,'Match Data'!$B$5:$B$2000,$A9),"") | O9: =IFERROR(AVERAGEIFS('Match Data'!$M$5:$M$2000,'Match Data'!$B$5:$B$2000,$A9),"") | P9: =IFERROR(maxifs('Session Log'!$B$5:$B$2000,'Session Log'!$E$5:$E$2000,$A9),"") -> 46091 | Q9: =IFERROR(maxifs('Match Data'!$C$5:$C$2000,'Match Data'!$B$5:$B$2000,$A9),"") -> 46090
A10: =IF('Player Profile'!B10="","",'Player Profile'!B10) -> Athray | B10: =IF(A10="","",'Player Profile'!K10) -> Yes | C10: =IF(A10="","",COUNTIFS('Session Log'!$E$5:$E$2000,$A10)) -> 14 | D10: =IF(A10="","",SUMIFS('Session Log'!$M$5:$M$2000,'Session Log'!$E$5:$E$2000,$A10)) -> 215 | E10: =IF(A10="","",COUNTIFS('Skill Metrics'!$B$5:$B$2000,$A10)) -> 0 | F10: =IFERROR(AVERAGEIFS('Skill Metrics'!$J$5:$J$2000,'Skill Metrics'!$B$5:$B$2000,$A10),"") | G10: =IFERROR(AVERAGEIFS('Skill Metrics'!$M$5:$M$2000,'Skill Metrics'!$B$5:$B$2000,$A10),"") | H10: =IFERROR(AVERAGEIFS('Skill Metrics'!$O$5:$O$2000,'Skill Metrics'!$B$5:$B$2000,$A10),"") | I10: =IF(A10="","",COUNTIFS('Match Data'!$B$5:$B$2000,$A10)) -> 5 | J10: =IF(A10="","",COUNTIFS('Match Data'!$B$5:$B$2000,$A10,'Match Data'!$I$5:$I$2000,"Win")) -> 3 | K10: =IFERROR(J10/I10,"") -> 0.6 | L10: =IFERROR(AVERAGEIFS('Match Data'!$J$5:$J$2000,'Match Data'!$B$5:$B$2000,$A10),"") -> 3 | M10: =IFERROR(AVERAGEIFS('Match Data'!$K$5:$K$2000,'Match Data'!$B$5:$B$2000,$A10),"") -> 2.5 | N10: =IFERROR(AVERAGEIFS('Match Data'!$L$5:$L$2000,'Match Data'!$B$5:$B$2000,$A10),"") -> 3.5 | O10: =IFERROR(AVERAGEIFS('Match Data'!$M$5:$M$2000,'Match Data'!$B$5:$B$2000,$A10),"") -> 2.5 | P10: =IFERROR(maxifs('Session Log'!$B$5:$B$2000,'Session Log'!$E$5:$E$2000,$A10),"") -> 46091 | Q10: =IFERROR(maxifs('Match Data'!$C$5:$C$2000,'Match Data'!$B$5:$B$2000,$A10),"") -> 46091
A11: =IF('Player Profile'!B11="","",'Player Profile'!B11) -> Arya | B11: =IF(A11="","",'Player Profile'!K11) -> Yes | C11: =IF(A11="","",COUNTIFS('Session Log'!$E$5:$E$2000,$A11)) -> 2 | D11: =IF(A11="","",SUMIFS('Session Log'!$M$5:$M$2000,'Session Log'!$E$5:$E$2000,$A11)) -> 30 | E11: =IF(A11="","",COUNTIFS('Skill Metrics'!$B$5:$B$2000,$A11)) -> 0 | F11: =IFERROR(AVERAGEIFS('Skill Metrics'!$J$5:$J$2000,'Skill Metrics'!$B$5:$B$2000,$A11),"") | G11: =IFERROR(AVERAGEIFS('Skill Metrics'!$M$5:$M$2000,'Skill Metrics'!$B$5:$B$2000,$A11),"") | H11: =IFERROR(AVERAGEIFS('Skill Metrics'!$O$5:$O$2000,'Skill Metrics'!$B$5:$B$2000,$A11),"") | I11: =IF(A11="","",COUNTIFS('Match Data'!$B$5:$B$2000,$A11)) -> 2 | J11: =IF(A11="","",COUNTIFS('Match Data'!$B$5:$B$2000,$A11,'Match Data'!$I$5:$I$2000,"Win")) -> 0 | K11: =IFERROR(J11/I11,"") -> 0 | L11: =IFERROR(AVERAGEIFS('Match Data'!$J$5:$J$2000,'Match Data'!$B$5:$B$2000,$A11),"") | M11: =IFERROR(AVERAGEIFS('Match Data'!$K$5:$K$2000,'Match Data'!$B$5:$B$2000,$A11),"") | N11: =IFERROR(AVERAGEIFS('Match Data'!$L$5:$L$2000,'Match Data'!$B$5:$B$2000,$A11),"") | O11: =IFERROR(AVERAGEIFS('Match Data'!$M$5:$M$2000,'Match Data'!$B$5:$B$2000,$A11),"") | P11: =IFERROR(maxifs('Session Log'!$B$5:$B$2000,'Session Log'!$E$5:$E$2000,$A11),"") -> 46090 | Q11: =IFERROR(maxifs('Match Data'!$C$5:$C$2000,'Match Data'!$B$5:$B$2000,$A11),"") -> 46090
A12: =IF('Player Profile'!B12="","",'Player Profile'!B12) -> Alan | B12: =IF(A12="","",'Player Profile'!K12) -> Yes | C12: =IF(A12="","",COUNTIFS('Session Log'!$E$5:$E$2000,$A12)) -> 0 | D12: =IF(A12="","",SUMIFS('Session Log'!$M$5:$M$2000,'Session Log'!$E$5:$E$2000,$A12)) -> 0 | E12: =IF(A12="","",COUNTIFS('Skill Metrics'!$B$5:$B$2000,$A12)) -> 0 | F12: =IFERROR(AVERAGEIFS('Skill Metrics'!$J$5:$J$2000,'Skill Metrics'!$B$5:$B$2000,$A12),"") | G12: =IFERROR(AVERAGEIFS('Skill Metrics'!$M$5:$M$2000,'Skill Metrics'!$B$5:$B$2000,$A12),"") | H12: =IFERROR(AVERAGEIFS('Skill Metrics'!$O$5:$O$2000,'Skill Metrics'!$B$5:$B$2000,$A12),"") | I12: =IF(A12="","",COUNTIFS('Match Data'!$B$5:$B$2000,$A12)) -> 0 | J12: =IF(A12="","",COUNTIFS('Match Data'!$B$5:$B$2000,$A12,'Match Data'!$I$5:$I$2000,"Win")) -> 0 | K12: =IFERROR(J12/I12,"") | L12: =IFERROR(AVERAGEIFS('Match Data'!$J$5:$J$2000,'Match Data'!$B$5:$B$2000,$A12),"") | M12: =IFERROR(AVERAGEIFS('Match Data'!$K$5:$K$2000,'Match Data'!$B$5:$B$2000,$A12),"") | N12: =IFERROR(AVERAGEIFS('Match Data'!$L$5:$L$2000,'Match Data'!$B$5:$B$2000,$A12),"") | O12: =IFERROR(AVERAGEIFS('Match Data'!$M$5:$M$2000,'Match Data'!$B$5:$B$2000,$A12),"") | P12: =IFERROR(maxifs('Session Log'!$B$5:$B$2000,'Session Log'!$E$5:$E$2000,$A12),"") -> 0 | Q12: =IFERROR(maxifs('Match Data'!$C$5:$C$2000,'Match Data'!$B$5:$B$2000,$A12),"") -> 0
A13: =IF('Player Profile'!B13="","",'Player Profile'!B13) -> Fedelesh | B13: =IF(A13="","",'Player Profile'!K13) -> Yes | C13: =IF(A13="","",COUNTIFS('Session Log'!$E$5:$E$2000,$A13)) -> 0 | D13: =IF(A13="","",SUMIFS('Session Log'!$M$5:$M$2000,'Session Log'!$E$5:$E$2000,$A13)) -> 0 | E13: =IF(A13="","",COUNTIFS('Skill Metrics'!$B$5:$B$2000,$A13)) -> 0 | F13: =IFERROR(AVERAGEIFS('Skill Metrics'!$J$5:$J$2000,'Skill Metrics'!$B$5:$B$2000,$A13),"") | G13: =IFERROR(AVERAGEIFS('Skill Metrics'!$M$5:$M$2000,'Skill Metrics'!$B$5:$B$2000,$A13),"") | H13: =IFERROR(AVERAGEIFS('Skill Metrics'!$O$5:$O$2000,'Skill Metrics'!$B$5:$B$2000,$A13),"") | I13: =IF(A13="","",COUNTIFS('Match Data'!$B$5:$B$2000,$A13)) -> 0 | J13: =IF(A13="","",COUNTIFS('Match Data'!$B$5:$B$2000,$A13,'Match Data'!$I$5:$I$2000,"Win")) -> 0 | K13: =IFERROR(J13/I13,"") | L13: =IFERROR(AVERAGEIFS('Match Data'!$J$5:$J$2000,'Match Data'!$B$5:$B$2000,$A13),"") | M13: =IFERROR(AVERAGEIFS('Match Data'!$K$5:$K$2000,'Match Data'!$B$5:$B$2000,$A13),"") | N13: =IFERROR(AVERAGEIFS('Match Data'!$L$5:$L$2000,'Match Data'!$B$5:$B$2000,$A13),"") | O13: =IFERROR(AVERAGEIFS('Match Data'!$M$5:$M$2000,'Match Data'!$B$5:$B$2000,$A13),"") | P13: =IFERROR(maxifs('Session Log'!$B$5:$B$2000,'Session Log'!$E$5:$E$2000,$A13),"") -> 0 | Q13: =IFERROR(maxifs('Match Data'!$C$5:$C$2000,'Match Data'!$B$5:$B$2000,$A13),"") -> 0
A14: =IF('Player Profile'!B14="","",'Player Profile'!B14) -> Vivek | B14: =IF(A14="","",'Player Profile'!K14) -> Yes | C14: =IF(A14="","",COUNTIFS('Session Log'!$E$5:$E$2000,$A14)) -> 0 | D14: =IF(A14="","",SUMIFS('Session Log'!$M$5:$M$2000,'Session Log'!$E$5:$E$2000,$A14)) -> 0 | E14: =IF(A14="","",COUNTIFS('Skill Metrics'!$B$5:$B$2000,$A14)) -> 0 | F14: =IFERROR(AVERAGEIFS('Skill Metrics'!$J$5:$J$2000,'Skill Metrics'!$B$5:$B$2000,$A14),"") | G14: =IFERROR(AVERAGEIFS('Skill Metrics'!$M$5:$M$2000,'Skill Metrics'!$B$5:$B$2000,$A14),"") | H14: =IFERROR(AVERAGEIFS('Skill Metrics'!$O$5:$O$2000,'Skill Metrics'!$B$5:$B$2000,$A14),"") | I14: =IF(A14="","",COUNTIFS('Match Data'!$B$5:$B$2000,$A14)) -> 0 | J14: =IF(A14="","",COUNTIFS('Match Data'!$B$5:$B$2000,$A14,'Match Data'!$I$5:$I$2000,"Win")) -> 0 | K14: =IFERROR(J14/I14,"") | L14: =IFERROR(AVERAGEIFS('Match Data'!$J$5:$J$2000,'Match Data'!$B$5:$B$2000,$A14),"") | M14: =IFERROR(AVERAGEIFS('Match Data'!$K$5:$K$2000,'Match Data'!$B$5:$B$2000,$A14),"") | N14: =IFERROR(AVERAGEIFS('Match Data'!$L$5:$L$2000,'Match Data'!$B$5:$B$2000,$A14),"") | O14: =IFERROR(AVERAGEIFS('Match Data'!$M$5:$M$2000,'Match Data'!$B$5:$B$2000,$A14),"") | P14: =IFERROR(maxifs('Session Log'!$B$5:$B$2000,'Session Log'!$E$5:$E$2000,$A14),"") -> 0 | Q14: =IFERROR(maxifs('Match Data'!$C$5:$C$2000,'Match Data'!$B$5:$B$2000,$A14),"") -> 0
A15: =IF('Player Profile'!B15="","",'Player Profile'!B15) -> Stephen | B15: =IF(A15="","",'Player Profile'!K15) -> Yes | C15: =IF(A15="","",COUNTIFS('Session Log'!$E$5:$E$2000,$A15)) -> 0 | D15: =IF(A15="","",SUMIFS('Session Log'!$M$5:$M$2000,'Session Log'!$E$5:$E$2000,$A15)) -> 0 | E15: =IF(A15="","",COUNTIFS('Skill Metrics'!$B$5:$B$2000,$A15)) -> 0 | F15: =IFERROR(AVERAGEIFS('Skill Metrics'!$J$5:$J$2000,'Skill Metrics'!$B$5:$B$2000,$A15),"") | G15: =IFERROR(AVERAGEIFS('Skill Metrics'!$M$5:$M$2000,'Skill Metrics'!$B$5:$B$2000,$A15),"") | H15: =IFERROR(AVERAGEIFS('Skill Metrics'!$O$5:$O$2000,'Skill Metrics'!$B$5:$B$2000,$A15),"") | I15: =IF(A15="","",COUNTIFS('Match Data'!$B$5:$B$2000,$A15)) -> 0 | J15: =IF(A15="","",COUNTIFS('Match Data'!$B$5:$B$2000,$A15,'Match Data'!$I$5:$I$2000,"Win")) -> 0 | K15: =IFERROR(J15/I15,"") | L15: =IFERROR(AVERAGEIFS('Match Data'!$J$5:$J$2000,'Match Data'!$B$5:$B$2000,$A15),"") | M15: =IFERROR(AVERAGEIFS('Match Data'!$K$5:$K$2000,'Match Data'!$B$5:$B$2000,$A15),"") | N15: =IFERROR(AVERAGEIFS('Match Data'!$L$5:$L$2000,'Match Data'!$B$5:$B$2000,$A15),"") | O15: =IFERROR(AVERAGEIFS('Match Data'!$M$5:$M$2000,'Match Data'!$B$5:$B$2000,$A15),"") | P15: =IFERROR(maxifs('Session Log'!$B$5:$B$2000,'Session Log'!$E$5:$E$2000,$A15),"") -> 0 | Q15: =IFERROR(maxifs('Match Data'!$C$5:$C$2000,'Match Data'!$B$5:$B$2000,$A15),"") -> 0
A16: =IF('Player Profile'!B16="","",'Player Profile'!B16) -> Srinivas | B16: =IF(A16="","",'Player Profile'!K16) -> Yes | C16: =IF(A16="","",COUNTIFS('Session Log'!$E$5:$E$2000,$A16)) -> 0 | D16: =IF(A16="","",SUMIFS('Session Log'!$M$5:$M$2000,'Session Log'!$E$5:$E$2000,$A16)) -> 0 | E16: =IF(A16="","",COUNTIFS('Skill Metrics'!$B$5:$B$2000,$A16)) -> 0 | F16: =IFERROR(AVERAGEIFS('Skill Metrics'!$J$5:$J$2000,'Skill Metrics'!$B$5:$B$2000,$A16),"") | G16: =IFERROR(AVERAGEIFS('Skill Metrics'!$M$5:$M$2000,'Skill Metrics'!$B$5:$B$2000,$A16),"") | H16: =IFERROR(AVERAGEIFS('Skill Metrics'!$O$5:$O$2000,'Skill Metrics'!$B$5:$B$2000,$A16),"") | I16: =IF(A16="","",COUNTIFS('Match Data'!$B$5:$B$2000,$A16)) -> 0 | J16: =IF(A16="","",COUNTIFS('Match Data'!$B$5:$B$2000,$A16,'Match Data'!$I$5:$I$2000,"Win")) -> 0 | K16: =IFERROR(J16/I16,"") | L16: =IFERROR(AVERAGEIFS('Match Data'!$J$5:$J$2000,'Match Data'!$B$5:$B$2000,$A16),"") | M16: =IFERROR(AVERAGEIFS('Match Data'!$K$5:$K$2000,'Match Data'!$B$5:$B$2000,$A16),"") | N16: =IFERROR(AVERAGEIFS('Match Data'!$L$5:$L$2000,'Match Data'!$B$5:$B$2000,$A16),"") | O16: =IFERROR(AVERAGEIFS('Match Data'!$M$5:$M$2000,'Match Data'!$B$5:$B$2000,$A16),"") | P16: =IFERROR(maxifs('Session Log'!$B$5:$B$2000,'Session Log'!$E$5:$E$2000,$A16),"") -> 0 | Q16: =IFERROR(maxifs('Match Data'!$C$5:$C$2000,'Match Data'!$B$5:$B$2000,$A16),"") -> 0
A17: =IF('Player Profile'!B17="","",'Player Profile'!B17) -> Elan | B17: =IF(A17="","",'Player Profile'!K17) -> Yes | C17: =IF(A17="","",COUNTIFS('Session Log'!$E$5:$E$2000,$A17)) -> 0 | D17: =IF(A17="","",SUMIFS('Session Log'!$M$5:$M$2000,'Session Log'!$E$5:$E$2000,$A17)) -> 0 | E17: =IF(A17="","",COUNTIFS('Skill Metrics'!$B$5:$B$2000,$A17)) -> 0 | F17: =IFERROR(AVERAGEIFS('Skill Metrics'!$J$5:$J$2000,'Skill Metrics'!$B$5:$B$2000,$A17),"") | G17: =IFERROR(AVERAGEIFS('Skill Metrics'!$M$5:$M$2000,'Skill Metrics'!$B$5:$B$2000,$A17),"") | H17: =IFERROR(AVERAGEIFS('Skill Metrics'!$O$5:$O$2000,'Skill Metrics'!$B$5:$B$2000,$A17),"") | I17: =IF(A17="","",COUNTIFS('Match Data'!$B$5:$B$2000,$A17)) -> 0 | J17: =IF(A17="","",COUNTIFS('Match Data'!$B$5:$B$2000,$A17,'Match Data'!$I$5:$I$2000,"Win")) -> 0 | K17: =IFERROR(J17/I17,"") | L17: =IFERROR(AVERAGEIFS('Match Data'!$J$5:$J$2000,'Match Data'!$B$5:$B$2000,$A17),"") | M17: =IFERROR(AVERAGEIFS('Match Data'!$K$5:$K$2000,'Match Data'!$B$5:$B$2000,$A17),"") | N17: =IFERROR(AVERAGEIFS('Match Data'!$L$5:$L$2000,'Match Data'!$B$5:$B$2000,$A17),"") | O17: =IFERROR(AVERAGEIFS('Match Data'!$M$5:$M$2000,'Match Data'!$B$5:$B$2000,$A17),"") | P17: =IFERROR(maxifs('Session Log'!$B$5:$B$2000,'Session Log'!$E$5:$E$2000,$A17),"") -> 0 | Q17: =IFERROR(maxifs('Match Data'!$C$5:$C$2000,'Match Data'!$B$5:$B$2000,$A17),"") -> 0
... A54: =IF('Player Profile'!B54="","",'Player Profile'!B54) | B54: =IF(A54="","",'Player Profile'!K54) | C54: =IF(A54="","",COUNTIFS('Session Log'!$E$5:$E$2000,$A54)) | D54: =IF(A54="","",SUMIFS('Session Log'!$M$5:$M$2000,'Session Log'!$E$5:$E$2000,$A54)) | E54: =IF(A54="","",COUNTIFS('Skill Metrics'!$B$5:$B$2000,$A54)) | F54: =IFERROR(AVERAGEIFS('Skill Metrics'!$J$5:$J$2000,'Skill Metrics'!$B$5:$B$2000,$A54),"") | G54: =IFERROR(AVERAGEIFS('Skill Metrics'!$M$5:$M$2000,'Skill Metrics'!$B$5:$B$2000,$A54),"") | H54: =IFERROR(AVERAGEIFS('Skill Metrics'!$O$5:$O$2000,'Skill Metrics'!$B$5:$B$2000,$A54),"") | I54: =IF(A54="","",COUNTIFS('Match Data'!$B$5:$B$2000,$A54)) | J54: =IF(A54="","",COUNTIFS('Match Data'!$B$5:$B$2000,$A54,'Match Data'!$I$5:$I$2000,"Win")) | K54: =IFERROR(J54/I54,"") | L54: =IFERROR(AVERAGEIFS('Match Data'!$J$5:$J$2000,'Match Data'!$B$5:$B$2000,$A54),"") | M54: =IFERROR(AVERAGEIFS('Match Data'!$K$5:$K$2000,'Match Data'!$B$5:$B$2000,$A54),"") | N54: =IFERROR(AVERAGEIFS('Match Data'!$L$5:$L$2000,'Match Data'!$B$5:$B$2000,$A54),"") | O54: =IFERROR(AVERAGEIFS('Match Data'!$M$5:$M$2000,'Match Data'!$B$5:$B$2000,$A54),"") | P54: =IFERROR(maxifs('Session Log'!$B$5:$B$2000,'Session Log'!$E$5:$E$2000,$A54),"") -> 0 | Q54: =IFERROR(maxifs('Match Data'!$C$5:$C$2000,'Match Data'!$B$5:$B$2000,$A54),"") -> 0
